Traceback (most recent call last):
  File "/Users/maxmcdonough/Projects/python-test/exercises/exceptions.py", line 12, in <module>
    raise Exception('this is the error message')
Exception: this is the error message
Traceback (most recent call last):
  File "/Users/maxmcdonough/Projects/python-test/exercises/exceptions.py", line 12, in <module>
    raise Exception('this is the error message')
Exception: this is the error message
